<?xml version="1.0"?>
<mujoco model="3r_arm">
    <option integrator="RK4" timestep="0.001" />
    <compiler angle="degree" />

    <visual>
        <map force="0.1" zfar="30" />
        <rgba haze="0.15 0.25 0.35 1" />
        <global offwidth="2560" offheight="1440" elevation="-20" azimuth="120" />
    </visual>

    <asset>
        <texture type="skybox" builtin="gradient" rgb1=".3 .5 .7" rgb2="0 0 0" width="32"
            height="512" />
        <texture name="body" type="cube" builtin="flat" mark="cross" width="128" height="128"
            rgb1="0.8 0.6 0.4" rgb2="0.8 0.6 0.4" markrgb="1 1 1" random="0.01" />
        <material name="body" texture="body" texuniform="true" rgba="0.8 0.6 .4 1" />
        <material name="grey" rgba="0.6 0.6 0.6 1" />
        <material name="green" rgba="0.6 0.9 0.6 1" />
        <material name="dark_green" rgba="0.3 0.6 .3 1" />
        <material name="dark_grey" rgba="0.3 0.3 .3 1" />
        <texture name="grid" type="2d" builtin="checker" width="512" height="512" rgb1=".1 .2 .3"
            rgb2=".2 .3 .4" />
        <material name="grid" texture="grid" texrepeat="1 1" texuniform="true" reflectance=".2" />
    </asset>

    <default>
        <joint type="hinge" limited="true" range="-180 180" axis="0 0 1" />
    </default>

    <worldbody>

        <geom name="floor" size="0 0 .001" type="plane" material="grid" condim="3" />
        <light name="spotlight" diffuse=".5 .8 .8" specular="0.3 0.3 0.3" pos="0 0 8" />

        <body name="base" pos="0 0 0.5">
            <geom type="cylinder" size="0.2 0.5" material="dark_grey" />

            <body name="link1" pos="0 0 1">
                <geom type="cylinder" size="0.08 0.5" material="dark_green" />
                <joint name="joint1" pos="0 0 0.5" />

                <body name="link2" pos="0.5 0 0.5" euler="0 90 0">
                    <geom type="cylinder" size="0.08 0.5" material="dark_grey" />

                    <body name="link3" pos="0.5 0 0.5" euler="90 0 0">
                        <joint name="joint2" pos="-0.5 0 0" />
                        <geom type="cylinder" size="0.08 0.5" euler="0 90 0" material="green" />

                        <body name="link4" pos="0.5 0.5 0" euler="-90 0 0">
                            <joint name="joint3" pos="0 0 -0.5" />
                            <site name="frame3_site" pos="0 0 -0.5" size="0.1" rgba="1 1 1 1" />

                            <geom type="cylinder" size="0.08 0.5" material="grey" />
                            <body name="ee" pos="0 0 0.5" euler="90 0 0">
                                <!-- <joint name="joint3" pos="0 0 0.5" axis="0 0 -1"/> -->
                                <geom type="cylinder" size="0.1 0.2" material="grey" />
                            </body>
                        </body>
                    </body>

                </body>
            </body>
        </body>
    </worldbody>

    <!-- <actuator>
        <motor name="torque_control" joint="joint1" ctrlrange="-10 10"/>  
        <position
        name="m1" joint="joint1" kp="2" kv="0.02" ctrlrange="-180 180" />
        <position name="m2"
        joint="joint2" kp="2" kv="0.02" ctrlrange="-180 180" />
        <position name="m3" joint="joint3"
        kp="2" kv="0.02" ctrlrange="-90 90" />
    </actuator> -->

</mujoco>
